<?xml version="1.0" encoding="utf-8"?>
<!-- This URDF was automatically created by SolidWorks to URDF Exporter! Originally created by Stephen Brawner (brawner@gmail.com) 
     Commit Version: 1.6.0-4-g7f85cfe  Build Version: 1.6.7995.38578
     For more information, please see http://wiki.ros.org/sw_urdf_exporter -->
<robot
  name="urdf4">
  <link
    name="base_link">
    <inertial>
      <origin
        xyz="0 -2.77555756156289E-17 0.04"
        rpy="0 0 0" />
      <mass
        value="0.15707963267949" />
      <inertia
        ixx="0.000391062835524979"
        ixy="-6.21980377065526E-36"
        ixz="9.88120452211026E-36"
        iyy="0.000391062835524979"
        iyz="7.61962617655533E-36"
        izz="0.000614574062858504" />
    </inertial>
    <visual>
      <origin
        xyz="0 0 0"
        rpy="0 0 0" />
      <geometry>
        <mesh
          filename="package://urdf4/meshes/base_link.STL" />
      </geometry>
      <material
        name="">
        <color
          rgba="0.792156862745098 0.819607843137255 0.933333333333333 1" />
      </material>
    </visual>
    <collision>
      <origin
        xyz="0 0 0"
        rpy="0 0 0" />
      <geometry>
        <mesh
          filename="package://urdf4/meshes/base_link.STL" />
      </geometry>
    </collision>
  </link>
  <link
    name="link1">
    <inertial>
      <origin
        xyz="0.00277146259382868 -0.000977617047691587 0.0392275940929765"
        rpy="0 0 0" />
      <mass
        value="0.10392584627471" />
      <inertia
        ixx="8.06918285221045E-05"
        ixy="2.30972045071662E-07"
        ixz="-1.9180114960661E-06"
        iyy="7.3013450070366E-05"
        iyz="2.74033815861125E-07"
        izz="0.000130206094147028" />
    </inertial>
    <visual>
      <origin
        xyz="0 0 0"
        rpy="0 0 0" />
      <geometry>
        <mesh
          filename="package://urdf4/meshes/link1.STL" />
      </geometry>
      <material
        name="">
        <color
          rgba="0.792156862745098 0.819607843137255 0.933333333333333 1" />
      </material>
    </visual>
    <collision>
      <origin
        xyz="0 0 0"
        rpy="0 0 0" />
      <geometry>
        <mesh
          filename="package://urdf4/meshes/link1.STL" />
      </geometry>
    </collision>
  </link>
  <joint
    name="joint1"
    type="revolute">
    <origin
      xyz="0 0 0"
      rpy="0 0 0" />
    <parent
      link="base_link" />
    <child
      link="link1" />
    <axis
      xyz="0 0 1" />
    <limit
      lower="-3.14"
      upper="3.14"
      effort="2.5"
      velocity="5.7596" />
  </joint>
  <link
    name="link2">
    <inertial>
      <origin
        xyz="0.0569964644660941 3.53553390591843E-06 0.0815648422319146"
        rpy="0 0 0" />
      <mass
        value="0.0258099114254626" />
      <inertia
        ixx="1.44147403776671E-05"
        ixy="1.83416759364335E-22"
        ixz="-4.84700932864664E-21"
        iyy="2.38689128817972E-05"
        iyz="-7.93441713352668E-22"
        izz="1.12484016319642E-05" />
    </inertial>
    <visual>
      <origin
        xyz="0 0 0"
        rpy="0 0 0" />
      <geometry>
        <mesh
          filename="package://urdf4/meshes/link2.STL" />
      </geometry>
      <material
        name="">
        <color
          rgba="0.792156862745098 0.819607843137255 0.933333333333333 1" />
      </material>
    </visual>
    <collision>
      <origin
        xyz="0 0 0"
        rpy="0 0 0" />
      <geometry>
        <mesh
          filename="package://urdf4/meshes/link2.STL" />
      </geometry>
    </collision>
  </link>
  <joint
    name="joint2"
    type="revolute">
    <origin
      xyz="0 0 0"
      rpy="0 0 0" />
    <parent
      link="link1" />
    <child
      link="link2" />
    <axis
      xyz="0 0 -1" />
    <limit
      lower="-3.14"
      upper="3.14"
      effort="2.5"
      velocity="5.7596" />
  </joint>
  <link
    name="link3">
    <inertial>
      <origin
        xyz="0.046197265017532 0.000921908863603743 0.0830187996806798"
        rpy="0 0 0" />
      <mass
        value="0.0698780274199756" />
      <inertia
        ixx="2.44614411888194E-05"
        ixy="1.52392496270811E-08"
        ixz="3.57093070464471E-07"
        iyy="4.70199977946402E-05"
        iyz="3.04492741754069E-08"
        izz="2.75333599269245E-05" />
    </inertial>
    <visual>
      <origin
        xyz="0 0 0"
        rpy="0 0 0" />
      <geometry>
        <mesh
          filename="package://urdf4/meshes/link3.STL" />
      </geometry>
      <material
        name="">
        <color
          rgba="0.792156862745098 0.819607843137255 0.933333333333333 1" />
      </material>
    </visual>
    <collision>
      <origin
        xyz="0 0 0"
        rpy="0 0 0" />
      <geometry>
        <mesh
          filename="package://urdf4/meshes/link3.STL" />
      </geometry>
    </collision>
  </link>
  <joint
    name="joint3"
    type="revolute">
    <origin
      xyz="0 0 0"
      rpy="0 0 0" />
    <parent
      link="link2" />
    <child
      link="link3" />
    <axis
      xyz="0 0 -1" />
    <limit
      lower="-3.14"
      upper="3.14"
      effort="2.5"
      velocity="5.7596" />
  </joint>
  <link
    name="link4">
    <inertial>
      <origin
        xyz="0.0314868755239737 0.00191709912704481 0.0215200689134932"
        rpy="0 0 0" />
      <mass
        value="0.0770831626214746" />
      <inertia
        ixx="1.81599660334155E-05"
        ixy="2.87203989654407E-06"
        ixz="4.28919539038616E-07"
        iyy="3.64659853084219E-05"
        iyz="5.40034548023297E-08"
        izz="3.35780702510269E-05" />
    </inertial>
    <visual>
      <origin
        xyz="0 0 0"
        rpy="0 0 0" />
      <geometry>
        <mesh
          filename="package://urdf4/meshes/link4.STL" />
      </geometry>
      <material
        name="">
        <color
          rgba="0.792156862745098 0.819607843137255 0.933333333333333 1" />
      </material>
    </visual>
    <collision>
      <origin
        xyz="0 0 0"
        rpy="0 0 0" />
      <geometry>
        <mesh
          filename="package://urdf4/meshes/link4.STL" />
      </geometry>
    </collision>
  </link>
  <joint
    name="joint4"
    type="revolute">
    <origin
      xyz="0 0 0"
      rpy="0 0 0" />
    <parent
      link="link3" />
    <child
      link="link4" />
    <axis
      xyz="0 0 -1" />
    <limit
      lower="-3.14"
      upper="3.14"
      effort="2.5"
      velocity="5.7596" />
  </joint>
  <link
    name="gripkiri">
    <inertial>
      <origin
        xyz="0.0140725750696402 -3.997863102502E-05 -0.0537459245884662"
        rpy="0 0 0" />
      <mass
        value="0.00468228410417343" />
      <inertia
        ixx="2.37887235512241E-07"
        ixy="-6.78988706974304E-08"
        ixz="-1.20558330153676E-22"
        iyy="2.06560886388221E-06"
        iyz="-1.10560177210667E-23"
        izz="2.29101000844999E-06" />
    </inertial>
    <visual>
      <origin
        xyz="0 0 0"
        rpy="0 0 0" />
      <geometry>
        <mesh
          filename="package://urdf4/meshes/gripkiri.STL" />
      </geometry>
      <material
        name="">
        <color
          rgba="0.792156862745098 0.819607843137255 0.933333333333333 1" />
      </material>
    </visual>
    <collision>
      <origin
        xyz="0 0 0"
        rpy="0 0 0" />
      <geometry>
        <mesh
          filename="package://urdf4/meshes/gripkiri.STL" />
      </geometry>
    </collision>
  </link>
  <joint
    name="gripkiri"
    type="revolute">
    <origin
      xyz="0.083525 0.077946 0.039501"
      rpy="-1.5708 0 0" />
    <parent
      link="link4" />
    <child
      link="gripkiri" />
    <axis
      xyz="0 0 -1" />
    <limit
      lower="-3.14"
      upper="3.14"
      effort="0.21575"
      velocity="10.47" />
  </joint>
  <link
    name="endkiri">
    <inertial>
      <origin
        xyz="-0.343708506679782 0.000102874868439212 0.0204662433594579"
        rpy="0 0 0" />
      <mass
        value="0.443141170884827" />
      <inertia
        ixx="0.00146787791830436"
        ixy="-1.44636011547406E-05"
        ixz="0.00186172597660297"
        iyy="0.00928119668905264"
        iyz="2.5196561944287E-06"
        izz="0.00867223786281813" />
    </inertial>
    <visual>
      <origin
        xyz="0 0 0"
        rpy="0 0 0" />
      <geometry>
        <mesh
          filename="package://urdf4/meshes/endkiri.STL" />
      </geometry>
      <material
        name="">
        <color
          rgba="1 1 1 1" />
      </material>
    </visual>
    <collision>
      <origin
        xyz="0 0 0"
        rpy="0 0 0" />
      <geometry>
        <mesh
          filename="package://urdf4/meshes/endkiri.STL" />
      </geometry>
    </collision>
  </link>
  <joint
    name="endkiri"
    type="fixed">
    <origin
      xyz="0.064689 0.017215 -0.051746"
      rpy="0 0 0" />
    <parent
      link="gripkiri" />
    <child
      link="endkiri" />
    <axis
      xyz="0 0 0" />
  </joint>
  <link
    name="gripkanan">
    <inertial>
      <origin
        xyz="0.0140530439209312 0.000742242506165516 -0.00199999999999999"
        rpy="0 0 0" />
      <mass
        value="0.00468228410417342" />
      <inertia
        ixx="2.3567072390795E-07"
        ixy="-2.35409753323601E-08"
        ixz="-2.85298576796313E-23"
        iyy="2.06782537548649E-06"
        iyz="1.69542094219708E-23"
        izz="2.29101000844998E-06" />
    </inertial>
    <visual>
      <origin
        xyz="0 0 0"
        rpy="0 0 0" />
      <geometry>
        <mesh
          filename="package://urdf4/meshes/gripkanan.STL" />
      </geometry>
      <material
        name="">
        <color
          rgba="0.792156862745098 0.819607843137255 0.933333333333333 1" />
      </material>
    </visual>
    <collision>
      <origin
        xyz="0 0 0"
        rpy="0 0 0" />
      <geometry>
        <mesh
          filename="package://urdf4/meshes/gripkanan.STL" />
      </geometry>
    </collision>
  </link>
  <joint
    name="gripkanan"
    type="revolute">
    <origin
      xyz="0.083475 0.0262 0.003701"
      rpy="-1.5708 0 0" />
    <parent
      link="link4" />
    <child
      link="gripkanan" />
    <axis
      xyz="0 0 -1" />
    <limit
      lower="-3.14"
      upper="3.14"
      effort="0.21575"
      velocity="10.47" />
  </joint>
  <link
    name="endkanan">
    <inertial>
      <origin
        xyz="-0.344437034985364 -0.00451712104558855 0.0204662433594592"
        rpy="0 0 0" />
      <mass
        value="0.443141170884827" />
      <inertia
        ixx="0.00146787791830436"
        ixy="-1.44636011547413E-05"
        ixz="0.00186172597660296"
        iyy="0.00928119668905264"
        iyz="2.519656194429E-06"
        izz="0.00867223786281813" />
    </inertial>
    <visual>
      <origin
        xyz="0 0 0"
        rpy="0 0 0" />
      <geometry>
        <mesh
          filename="package://urdf4/meshes/endkanan.STL" />
      </geometry>
      <material
        name="">
        <color
          rgba="1 1 1 1" />
      </material>
    </visual>
    <collision>
      <origin
        xyz="0 0 0"
        rpy="0 0 0" />
      <geometry>
        <mesh
          filename="package://urdf4/meshes/endkanan.STL" />
      </geometry>
    </collision>
  </link>
  <joint
    name="endkanan"
    type="fixed">
    <origin
      xyz="0.0654673705371463 -0.0139650776923003 0"
      rpy="0 0 0" />
    <parent
      link="gripkanan" />
    <child
      link="endkanan" />
    <axis
      xyz="0 0 0" />
  </joint>
</robot>